<?xml version="1.0" encoding="utf-8"?>
<!-- This URDF was automatically created by SolidWorks to URDF Exporter! Originally created by Stephen Brawner (brawner@gmail.com) 
     Commit Version: 1.6.0-4-g7f85cfe  Build Version: 1.6.7995.38578
     For more information, please see http://wiki.ros.org/sw_urdf_exporter -->
<robot
  xmlns:xacro="http://ros.org/wiki/xacro" name="Pokeye">

  <!-- Define robot constants -->
  <xacro:property name="turret_height" value="0.162"/>
  <xacro:property name="bar_thickness" value="0.04"/>
  <xacro:property name="wheel_radius" value="0.125"/>
  <xacro:property name="wheel_zoff" value="0.05"/>
  <xacro:property name="friction_coefficient_1" value="10"/>
  <xacro:property name="friction_coefficient_2" value="10"/>
  <xacro:property name="support_height" value="0.509"/>

  <!-- ===== Drill tool-tip frame =========================================== -->
  <!-- `drill_tip` is a fixed frame at the tip of the drill bit, rigidly       -->
  <!-- attached to the last moving link (gantry_rotate_link). The drill body   -->
  <!-- extends along -Z of gantry_rotate_link (see its collision box, which    -->
  <!-- spans z = 0 .. -0.15). These offsets are a PLACEHOLDER: measure the     -->
  <!-- real bit-tip position/orientation on the tool and update them here.     -->
  <xacro:property name="drill_tip_x" value="-0.40"/>
  <xacro:property name="drill_tip_y" value="0.0"/>
  <xacro:property name="drill_tip_z" value="0.10"/>
  <xacro:property name="drill_tip_roll" value="0.0"/>
  <xacro:property name="drill_tip_pitch" value="-1.5708"/>
  <xacro:property name="drill_tip_yaw" value="0.0"/>

  <link
    name="base_link">
    <inertial>
      <!-- CoM biased forward along +x of base_link (toward the turret/front) -->
      <origin
        xyz="0.30 0.0 0.0"
        rpy="0 0 0" />
      <mass value="15.0"/>
      <inertia
        ixx="0.25404237445799095"
        ixy="1.4121324289112278e-14"
        ixz="-0.003497109609384773"
        iyy="0.41070585079970945"
        iyz="-2.0397902292779115e-16"
        izz="0.50178022389242"/>
    </inertial>
    <visual>
      <origin
        xyz="-0.075 0 0.22"
        rpy="1.5708 0 1.5708" />
      <geometry>
        <mesh
          filename="package://robo_drill/robo_drill_description/meshes/d_base_v2.stl"  scale="0.001 0.001 0.001"/>
      </geometry>
      <material
        name="">
        <color
          rgba="0.792156862745098 0.819607843137255 0.933333333333333 1" />
      </material>
    </visual>
    <collision>
      <origin
        xyz="-0.075 0 0.22"
        rpy="1.5708 0 1.5708" />
      <geometry>
        <mesh
          filename="package://robo_drill/robo_drill_description/meshes/d_base_v2.stl"  scale="0.001 0.001 0.001"/>
      </geometry>
    </collision>
  </link>
  <link
    name="drivewhl_r_joint_link">
    <inertial>
      <origin
        xyz="-2.77555756156289E-17 1.38777878078145E-17 -0.00433895556276356"
        rpy="0 0 0" />
      <mass
        value="27.24055354973625" />
      <inertia
        ixx="0.135985035679444"
        ixy="19.4114540522268E-18"
        ixz="-49.1257109838198E-19"
        iyy="0.135985035679444"
        iyz="-7.4177739827845E-18"
        izz="0.2031187280856825" />
    </inertial>
    <visual>
      <origin
        xyz="0 0 0"
        rpy="0 1.5708 0" />
      <geometry>
        <mesh
          filename="package://robo_drill/robo_drill_description/meshes/right_wheel.STL" />
      </geometry>
      <material
        name="">
        <color
          rgba="0.0 0.0 0.0 1" />
      </material>
    </visual>
    <collision>
      <origin
        xyz="0 0 0"
        rpy="0 1.5708 0" />
      <geometry>
        <mesh
          filename="package://robo_drill/robo_drill_description/meshes/right_wheel.STL" />
      </geometry>
    </collision>
  </link>
  <joint
    name="drivewhl_r_joint"
    type="continuous">
    <origin
      xyz="0 -0.40275 0"
      rpy="-1.5708 0 0" />
    <parent
      link="base_link" />
    <child
      link="drivewhl_r_joint_link" />
    <axis
      xyz="0 0 1" />
    <limit effort="500.0" velocity="50.0"/>
  </joint>
  <link
    name="drivewhl_l_joint_link">
    <inertial>
      <origin
        xyz="2.77555756156289E-17 0 -0.00433895556276352"
        rpy="0 0 0" />
      <mass
        value="27.24055354973625" />
      <inertia
        ixx="0.135985035679444"
        ixy="-10.52150798691795E-18"
        ixz="11.5717039611713E-19"
        iyy="0.135985035679444"
        iyz="28.7983624641597E-19"
        izz="0.2031187280856825" />
    </inertial>
    <visual>
      <origin
        xyz="0 0 0"
        rpy="0 -1.5708 0" />
      <geometry>
        <mesh
          filename="package://robo_drill/robo_drill_description/meshes/left_wheel.STL" />
      </geometry>
      <material
        name="">
        <color
          rgba="0.0 0.0 0.0 1" />
      </material>
    </visual>
    <collision>
      <origin
        xyz="0 0 0"
        rpy="0 -1.5708 0" />
      <geometry>
        <mesh
          filename="package://robo_drill/robo_drill_description/meshes/left_wheel.STL" />
      </geometry>
    </collision>
  </link>
  <joint
    name="drivewhl_l_joint"
    type="continuous">
    <origin
      xyz="0 0.40275 0"
      rpy="-1.5708 0 0" />
    <parent
      link="base_link" />
    <child
      link="drivewhl_l_joint_link" />
    <axis
      xyz="0 0 1" />
    <limit effort="500.0" velocity="50.0"/>
  </joint>
  <link
    name="turret_link">
    <inertial>
      <origin
        xyz="0.40 0 0.05"
        rpy="0 0 0" />
      <mass value="10.0"/>
      <inertia
        ixx="0.625"
        ixy="0.0"
        ixz="0.0"
        iyy="0.875"
        iyz="0.0"
        izz="0.875"/>
    </inertial>
    <visual>
      <origin
        xyz="0 0 0"
        rpy="1.5708 0 1.5708" />
      <geometry>
        <mesh
          filename="package://robo_drill/robo_drill_description/meshes/d_p_estructura_redesing.stl" scale="0.001 0.001 0.001"/>
      </geometry>
      <material
        name="">
        <color
          rgba="0.792156862745098 0.819607843137255 0.933333333333333 1" />
      </material>
    </visual>
    <!-- Fixed outer sleeve for the vertical (Z) gantry stage.
         The prismatic child link (gantry_lift1_link) is the moving inner stage; this
         sleeve keeps the structure visually connected when the stage is extended. -->
    <visual>
      <origin
        xyz="0.28 0.07 -0.047"
        rpy="0 0 3.1416" />
      <geometry>
        <mesh
          filename="package://robo_drill/robo_drill_description/meshes/d_e_stage_1_v3.stl" scale="0.001 0.001 0.001"/>
      </geometry>
      <material
        name="">
        <color
          rgba="0.792156862745098 0.819607843137255 0.933333333333333 1" />
      </material>
    </visual>
    <collision>
      <origin
        xyz="0 0 0"
        rpy="1.5708 0 1.5708" />
      <geometry>
        <mesh
          filename="package://robo_drill/robo_drill_description/meshes/d_e_stage_1_v3.stl" scale="0.001 0.001 0.001"/>
      </geometry>
    </collision>
  </link>
  <joint
    name="turret_joint"
    type="continuous">
    <origin
      xyz="0.40 0 0.2575"
      rpy="0 0 0" />
    <parent
      link="base_link" />
    <child
      link="turret_link" />
    <axis
      xyz="0 0 1" />
  </joint>  
  
  <link name="base_footprint"/>

  <joint name="base_joint" type="fixed">
      <parent link="base_footprint"/>
      <child link="base_link"/>
      <origin xyz="-0.167 0.0 0.125" rpy="0 0 0"/>
  </joint>

  <!-- Hidden support casters for Gazebo physics.
       The full turret STL already contains the visible caster geometry, but
       using that detailed mesh as the contact surface makes the turret legs
       take the load before the drive wheels. These simple spheres provide
       stable, low-friction support at the leg contact points. -->
  <link name="turret_caster_fl">
    <inertial>
      <origin xyz="0 0 0" rpy="0 0 0"/>
      <mass value="0.025"/>
      <inertia ixx="0.00005" ixy="0.0" ixz="0.0" iyy="0.00005" iyz="0.0" izz="0.00005"/>
    </inertial>
    <collision>
      <origin xyz="0 0 0" rpy="0 0 0"/>
      <geometry>
        <sphere radius="0.045"/>
      </geometry>
    </collision>
  </link>

  <joint name="turret_caster_fl_joint" type="fixed">
    <origin xyz="-0.3848 0.2810 -0.335" rpy="0 0 0"/>
    <parent link="turret_link"/>
    <child link="turret_caster_fl"/>
  </joint>

  <link name="turret_caster_fr">
    <inertial>
      <origin xyz="0 0 0" rpy="0 0 0"/>
      <mass value="0.025"/>
      <inertia ixx="0.00005" ixy="0.0" ixz="0.0" iyy="0.00005" iyz="0.0" izz="0.00005"/>
    </inertial>
    <collision>
      <origin xyz="0 0 0" rpy="0 0 0"/>
      <geometry>
        <sphere radius="0.045"/>
      </geometry>
    </collision>
  </link>

  <joint name="turret_caster_fr_joint" type="fixed">
    <origin xyz="-0.3820 -0.2838 -0.335" rpy="0 0 0"/>
    <parent link="turret_link"/>
    <child link="turret_caster_fr"/>
  </joint>

  <link name="turret_caster_bl">
    <inertial>
      <origin xyz="0 0 0" rpy="0 0 0"/>
      <mass value="0.025"/>
      <inertia ixx="0.00005" ixy="0.0" ixz="0.0" iyy="0.00005" iyz="0.0" izz="0.00005"/>
    </inertial>
    <collision>
      <origin xyz="0 0 0" rpy="0 0 0"/>
      <geometry>
        <sphere radius="0.045"/>
      </geometry>
    </collision>
  </link>

  <joint name="turret_caster_bl_joint" type="fixed">
    <origin xyz="0.3820 0.2838 -0.335" rpy="0 0 0"/>
    <parent link="turret_link"/>
    <child link="turret_caster_bl"/>
  </joint>

  <link name="turret_caster_br">
    <inertial>
      <origin xyz="0 0 0" rpy="0 0 0"/>
      <mass value="0.025"/>
      <inertia ixx="0.00005" ixy="0.0" ixz="0.0" iyy="0.00005" iyz="0.0" izz="0.00005"/>
    </inertial>
    <collision>
      <origin xyz="0 0 0" rpy="0 0 0"/>
      <geometry>
        <sphere radius="0.045"/>
      </geometry>
    </collision>
  </link>

  <joint name="turret_caster_br_joint" type="fixed">
    <origin xyz="0.3848 -0.2810 -0.335" rpy="0 0 0"/>
    <parent link="turret_link"/>
    <child link="turret_caster_br"/>
  </joint>


  
  <link
    name="gantry_lift1_link">
    <inertial>
      <origin
        xyz="0 0 0.0"
        rpy="0 0 0" />
      <mass value="0.5"/>
      <inertia
        ixx="0.022470833333333335"
        ixy="0.0"
        ixz="0.0"
        iyy="0.022354166666666668"
        iyz="0.0"
        izz="0.0004166666666666667"/>
    </inertial>
    <visual>
      <origin
        xyz="0.12 0.036 0.38"
        rpy="0.0262 0 0" />
      <geometry>
        <mesh
          filename="package://robo_drill/robo_drill_description/meshes/d_e_stage_2_v3.stl" scale="0.001 0.001 0.001"/>
      </geometry>
      <material
        name="">
        <color
          rgba="0.792156862745098 0.819607843137255 0.933333333333333 1" />
      </material>
    </visual>
    <collision>
      <origin
        xyz="0.12 0.036 0.38"
        rpy="0.0262 0 0" />
      <geometry>
        <mesh
          filename="package://robo_drill/robo_drill_description/meshes/d_e_stage_2_v3.stl" scale="0.001 0.001 0.001"/>
      </geometry>
    </collision>
  </link>
  <joint
    name="gantry_lift1_joint"
    type="prismatic">
    <origin
      xyz="0.2905 0 0"
      rpy="0 0 0" />
    <parent
      link="turret_link" />
    <child
      link="gantry_lift1_link" />
        <axis
    xyz="0 0 1" />
  <limit
    lower="-0.47"
    upper="0.40"
    effort="1000.0"
    velocity="0.1" />
  </joint>

  <!-- ============================================================= -->
  <!-- Pokeye 3-stage linear-actuator gantry + end rotation.         -->
  <!-- Stage 1 (gantry_lift1_joint) vertical lift is the joint above. -->
  <!-- Stage 2 (gantry_lift2_joint) second vertical lift.             -->
  <!-- Stage 3 (gantry_lateral_joint) horizontal lateral motion (Y). -->
  <!-- Stage 4 (gantry_rotate_joint) tool rotation about Z.           -->
  <!-- Geometry is placeholder rectangular prisms; refine as needed. -->
  <!-- ============================================================= -->

  <!-- Stage 2 - second vertical lift, mounted on top of stage 1 -->
  <link name="gantry_lift2_link">
    <inertial>
      <origin xyz="0 0 0.05" rpy="0 0 0" />
      <mass value="1.5" />
      <inertia ixx="0.0325" ixy="0.0" ixz="0.0"
               iyy="0.00305" iyz="0.0" izz="0.03305" />
    </inertial>
    <visual>
      <origin xyz="0 -0.265 0.1" rpy="1.5708 0 1.5708" />
      <geometry>
        <mesh
          filename="package://robo_drill/robo_drill_description/meshes/d_e_stage_3_v3.stl" scale="0.001 0.001 0.001"/>
      </geometry>
      <material name="">
        <color rgba="0.792156862745098 0.819607843137255 0.933333333333333 1" />
      </material>
    </visual>
    <collision>
      <origin xyz="0 -0.265 0.1" rpy="1.5708 0 1.5708" />
      <geometry>
        <mesh
          filename="package://robo_drill/robo_drill_description/meshes/d_e_stage_3_v3.stl" scale="0.001 0.001 0.001"/>
      </geometry>
    </collision>
  </link>
  <joint name="gantry_lift2_joint" type="prismatic">
    <origin xyz="0.19 0 0.423" rpy="0 0 0" />
    <parent link="gantry_lift1_link" />
    <child link="gantry_lift2_link" />
    <axis xyz="0 0 1" />
    <limit lower="0.0" upper="1.0" effort="500.0" velocity="0.2" />
  </joint>

  <!-- Stage 3 - lateral (horizontal Y) beam, mounted on the stage 2 carriage -->
  <link name="gantry_lateral_link">
    <inertial>
      <origin xyz="0.15 0 0.05" rpy="0 0 0" />
      <mass value="1.0" />
      <inertia ixx="0.00165" ixy="0.0" ixz="0.0"
               iyy="0.02165" iyz="0.0" izz="0.02165" />
    </inertial>
    <visual>
      <origin xyz="0.059 0.065 -0.09" rpy="0 0 1.5708" />
      <geometry>
        <mesh
          filename="package://robo_drill/robo_drill_description/meshes/rotatory-RL_D_50_102_48_01035.stl" scale="0.001 0.001 0.001"/>
      </geometry>
      <material name="">
        <color rgba="0.792156862745098 0.819607843137255 0.933333333333333 1" />
      </material>
    </visual>
    <collision>
      <origin xyz="0.059 0.065 -0.09" rpy="0 0 1.5708" />
      <geometry>
        <mesh
          filename="package://robo_drill/robo_drill_description/meshes/rotatory-RL_D_50_102_48_01035.stl" scale="0.001 0.001 0.001"/>
      </geometry>
    </collision>
  </link>
  <joint name="gantry_lateral_joint" type="prismatic">
    <origin xyz="0 0 0.10" rpy="0 0 0" />
    <parent link="gantry_lift2_link" />
    <child link="gantry_lateral_link" />
    <axis xyz="0 1 0" />
    <limit lower="-0.196" upper="0.196" effort="500.0" velocity="0.2" />
  </joint>

  <!-- End rotation - tool that rotates about Z, at the front of the reach beam -->
  <link name="gantry_rotate_link">
    <inertial>
      <origin xyz="0 0 -0.075" rpy="0 0 0" />
      <mass value="0.5" />
      <inertia ixx="0.0012" ixy="0.0" ixz="0.0"
               iyy="0.0012" iyz="0.0" izz="0.00055" />
    </inertial>
    <collision>
      <origin xyz="0 0 -0.075" rpy="0 0 0" />
      <geometry>
        <box size="0.08 0.08 0.15" />
      </geometry>
    </collision>
  </link>
  <joint name="gantry_rotate_joint" type="revolute">
    <origin xyz="0.06 0.06 0.0" rpy="1.5708 0 1.5708" />
    <parent link="gantry_lateral_link" />
    <child link="gantry_rotate_link" />
    <axis xyz="0 0 1" />
    <limit lower="-3.1416" upper="3.1416" effort="100.0" velocity="1.0" />
  </joint>

  <!-- Drill tool-tip frame: fixed to the end-rotation link. robot_state_publisher -->
  <!-- emits its TF automatically (no controller/ros2_control entry needed). -->
  <link name="drill_tip"/>
  <joint name="drill_tip_joint" type="fixed">
    <origin
      xyz="${drill_tip_x} ${drill_tip_y} ${drill_tip_z}"
      rpy="${drill_tip_roll} ${drill_tip_pitch} ${drill_tip_yaw}" />
    <parent link="gantry_rotate_link" />
    <child link="drill_tip" />
  </joint>

  <!-- Add Gazebo materials for the pokeye links -->
  <gazebo reference="base_link">
      <collide_bitmask>0</collide_bitmask>
  </gazebo>

  <gazebo reference="turret_link">
      <collide_bitmask>0</collide_bitmask>
      <gravity>false</gravity>
  </gazebo>

  <gazebo reference="gantry_lift1_link">
    <collide_bitmask>0</collide_bitmask>
    <gravity>false</gravity>
  </gazebo>

  <gazebo reference="gantry_lift2_link">
    <collide_bitmask>0</collide_bitmask>
    <gravity>false</gravity>
  </gazebo>

  <gazebo reference="gantry_lateral_link">
    <collide_bitmask>0</collide_bitmask>
    <gravity>false</gravity>
  </gazebo>

  <gazebo reference="gantry_rotate_link">
    <collide_bitmask>0</collide_bitmask>
    <gravity>false</gravity>
  </gazebo>

  <gazebo reference="drivewhl_l_joint_link">
      <mu1>2.0</mu1>
      <mu2>2.0</mu2>
      <kp>5000000.0</kp>
      <kd>10.0</kd>
      <minDepth>0.002</minDepth>
      <maxVel>50.0</maxVel>
      <!-- <fdir1>1 0 0</fdir1> -->
  </gazebo>

  <gazebo reference="drivewhl_r_joint_link">
      <mu1>2.0</mu1>
      <mu2>2.0</mu2>
      <kp>5000000.0</kp>
      <kd>10.0</kd>
      <minDepth>0.002</minDepth>
      <maxVel>50.0</maxVel>
      <!-- <fdir1>1 0 0</fdir1> -->
  </gazebo>

  <!-- Add damping to wheel joints -->
  <gazebo reference="drivewhl_l_joint">
      <provideFeedback>true</provideFeedback>
  </gazebo>

  <gazebo reference="drivewhl_r_joint">
      <provideFeedback>true</provideFeedback>
  </gazebo>

  <gazebo reference="turret_caster_fl">
      <mu1>0.001</mu1>
      <mu2>0.001</mu2>
      <kp>1000000.0</kp>
      <kd>50.0</kd>
      <minDepth>0.001</minDepth>
      <maxVel>0.1</maxVel>
  </gazebo>

  <gazebo reference="turret_caster_fr">
      <mu1>0.001</mu1>
      <mu2>0.001</mu2>
      <kp>1000000.0</kp>
      <kd>50.0</kd>
      <minDepth>0.001</minDepth>
      <maxVel>0.1</maxVel>
  </gazebo>

  <gazebo reference="turret_caster_bl">
      <mu1>0.001</mu1>
      <mu2>0.001</mu2>
      <kp>1000000.0</kp>
      <kd>50.0</kd>
      <minDepth>0.001</minDepth>
      <maxVel>0.1</maxVel>
  </gazebo>

  <gazebo reference="turret_caster_br">
      <mu1>0.001</mu1>
      <mu2>0.001</mu2>
      <kp>1000000.0</kp>
      <kd>50.0</kd>
      <minDepth>0.001</minDepth>
      <maxVel>0.1</maxVel>
  </gazebo>
  
</robot>
